Workbook

Sheet Upcoming Checkouts
A1: Scheduled (Upcoming) Shelter Checkouts
A2: Checkouts for the five shelters whose delivery date falls on or after 19 Sep 2026. Source: checkouts_template_2025-01-01_to_2027-12-31.xlsx, sheet "Checkouts (Template)".
A4: Shelter | B4: Delivery Date | C4: Timing | D4: Checkout # | E4: Customer # | F4: Customer Name | G4: Subscription Plan | H4: Wunderbar | I4: Invoice Date | J4: Payment Date Captured | K4: End of Subscription | L4: Items | M4: Delivery Dates | N4: Subscription Status | O4: Subtotal | P4: Discount | Q4: Amount | R4: VAT Amount | S4: Delivery Charge | T4: Region | U4: Status | V4: Payment Type | W4: Checkout Type | X4: Donation | Y4: Comments | Z4: Attempt Count
A5: Haven of Hope | B5: 46286 | C5: Upcoming | D5: 75015 | E5: 41785 | F5: Haven Of Hope Rescue | G5: - | H5: No | I5: 46253 | K5: - | L5: Samples x 1 | M5: 21-09-2026 | N5: Not Subscribed | O5: 0 | P5: 0 | Q5: 0 | R5: 0 | S5: 0 | T5: Dubai | U5: Successful | V5: Complimentary | W5: Separate Invoice | X5: No
A6: Stray Dogs Center | B6: 46290 | C6: Upcoming | D6: 75006 | E6: 40246 | F6: Stray Dogs Center | G6: - | H6: No | I6: 46253 | K6: - | L6: Samples x 1 | M6: 25-09-2026 | N6: Not Subscribed | O6: 0 | P6: 0 | Q6: 25 | R6: 1.19 | S6: 25 | T6: Umm Al Quwain | U6: Abandoned | V6: Manual Credit Card | W6: Separate Invoice | X6: No
A7: Haven of Hope | B7: 46300 | C7: Upcoming | D7: 76265 | E7: 41785 | F7: Haven Of Hope Rescue | G7: - | H7: No | I7: 46280 | K7: - | L7: Samples x 1 | M7: 05-10-2026 | N7: Not Subscribed | O7: 0 | P7: 0 | Q7: 0 | R7: 0 | S7: 0 | T7: Dubai | U7: Successful | V7: Complimentary | W7: Separate Invoice | X7: No | Y7: Gift a Meal for Haven of Hope, already marked as successful in donation deliveries
A8: Stray Dogs Center | B8: 46304 | C8: Upcoming | D8: 75007 | E8: 40246 | F8: Stray Dogs Center | G8: - | H8: No | I8: 46253 | K8: - | L8: Samples x 1 | M8: 09-10-2026 | N8: Not Subscribed | O8: 0 | P8: 0 | Q8: 25 | R8: 1.19 | S8: 25 | T8: Umm Al Quwain | U8: Abandoned | V8: Manual Credit Card | W8: Separate Invoice | X8: No
A9: Stray Dogs Center | B9: 46318 | C9: Upcoming | D9: 75008 | E9: 40246 | F9: Stray Dogs Center | G9: - | H9: No | I9: 46253 | K9: - | L9: Samples x 1 | M9: 23-10-2026 | N9: Not Subscribed | O9: 0 | P9: 0 | Q9: 25 | R9: 1.19 | S9: 25 | T9: Umm Al Quwain | U9: Abandoned | V9: Manual Credit Card | W9: Separate Invoice | X9: No
A11: Upcoming checkouts | B11: =COUNTA(D5:D9)

Sheet All Shelter Checkouts
A1: All Checkouts - Five Shelters (2025-2027 export)
A2: Every checkout in the source export for the five shelters, grouped by shelter and ordered by delivery date. Rows shaded yellow are the upcoming ones repeated on the "Upcoming Checkouts" tab.
A4: Shelter | B4: Delivery Date | C4: Timing | D4: Checkout # | E4: Customer # | F4: Customer Name | G4: Subscription Plan | H4: Wunderbar | I4: Invoice Date | J4: Payment Date Captured | K4: End of Subscription | L4: Items | M4: Delivery Dates | N4: Subscription Status | O4: Subtotal | P4: Discount | Q4: Amount | R4: VAT Amount | S4: Delivery Charge | T4: Region | U4: Status | V4: Payment Type | W4: Checkout Type | X4: Donation | Y4: Comments | Z4: Attempt Count
A5: Stray Dogs Center | B5: 45976 | C5: Past | D5: 64218 | E5: 40246 | F5: Stray Dogs Center | G5: - | H5: No | I5: 45976 | K5: - | L5: Gift a Meal AED 140 x 6 | M5: 15-11-2025 | N5: Not Subscribed | O5: 0 | P5: 0 | Q5: 25 | R5: 1.19 | S5: 25 | T5: Umm Al Quwain | U5: Abandoned | V5: Manual Credit Card | W5: Separate Invoice | X5: No
A6: Stray Dogs Center | B6: 45983 | C6: Past | D6: 64609 | E6: 40246 | F6: Stray Dogs Center | G6: - | H6: No | I6: 45982 | J6: 45982 | K6: - | L6: Samples x 1 | M6: 22-11-2025 | N6: Not Subscribed | O6: 0 | P6: 0 | Q6: 25 | R6: 1.19 | S6: 25 | T6: Umm Al Quwain | U6: Successful | V6: Cash | W6: Separate Invoice | X6: No
A7: Stray Dogs Center | B7: 46003 | C7: Past | D7: 65425 | E7: 40246 | F7: Stray Dogs Center | G7: - | H7: No | I7: 46002 | J7: 46002 | K7: - | L7: Gift a Meal AED 140 x 1 | M7: 12-12-2025 | N7: Not Subscribed | O7: 0 | P7: 0 | Q7: 25 | R7: 1.19 | S7: 25 | T7: Umm Al Quwain | U7: Successful | V7: Cash | W7: Separate Invoice | X7: No
A8: Stray Dogs Center | B8: 46010 | C8: Past | D8: 65544 | E8: 40246 | F8: Stray Dogs Center | G8: - | H8: No | I8: 46006 | J8: 46006 | K8: - | L8: Gift a Meal AED 140 x 1 | M8: 19-12-2025 | N8: Not Subscribed | O8: 0 | P8: 0 | Q8: 25 | R8: 1.19 | S8: 25 | T8: Umm Al Quwain | U8: Successful | V8: Manual Credit Card | W8: Separate Invoice | X8: No
A9: Stray Dogs Center | B9: 46017 | C9: Past | D9: 65545 | E9: 40246 | F9: Stray Dogs Center | G9: - | H9: No | I9: 46006 | J9: 46006 | K9: - | L9: Gift a Meal AED 140 x 1 | M9: 26-12-2025 | N9: Not Subscribed | O9: 0 | P9: 0 | Q9: 25 | R9: 1.19 | S9: 25 | T9: Umm Al Quwain | U9: Successful | V9: Manual Credit Card | W9: Separate Invoice | X9: No
A10: Stray Dogs Center | B10: 46024 | C10: Past | D10: 65546 | E10: 40246 | F10: Stray Dogs Center | G10: - | H10: No | I10: 46006 | J10: 46006 | K10: - | L10: Gift a Meal AED 140 x 1 | M10: 02-01-2026 | N10: Not Subscribed | O10: 0 | P10: 0 | Q10: 25 | R10: 1.19 | S10: 25 | T10: Umm Al Quwain | U10: Successful | V10: Manual Credit Card | W10: Separate Invoice | X10: No
A11: Stray Dogs Center | B11: 46031 | C11: Past | D11: 65547 | E11: 40246 | F11: Stray Dogs Center | G11: - | H11: No | I11: 46006 | J11: 46006 | K11: - | L11: Gift a Meal AED 140 x 1 | M11: 09-01-2026 | N11: Not Subscribed | O11: 0 | P11: 0 | Q11: 25 | R11: 1.19 | S11: 25 | T11: Umm Al Quwain | U11: Successful | V11: Manual Credit Card | W11: Separate Invoice | X11: No
A12: Stray Dogs Center | B12: 46038 | C12: Past | D12: 66617 | E12: 40246 | F12: Stray Dogs Center | G12: - | H12: No | I12: 46037 | J12: 46037 | K12: - | L12: Samples x 1 | M12: 16-01-2026 | N12: Not Subscribed | O12: 0 | P12: 0 | Q12: 25 | R12: 1.19 | S12: 25 | T12: Umm Al Quwain | U12: Successful | V12: Manual Credit Card | W12: Separate Invoice | X12: No
A13: Stray Dogs Center | B13: 46045 | C13: Past | D13: 66844 | E13: 40246 | F13: Stray Dogs Center | G13: - | H13: No | I13: 46043 | J13: 46043.719 | K13: - | L13: Samples x 1 | M13: 23-01-2026 | N13: Not Subscribed | O13: 0 | P13: 0 | Q13: 25 | R13: 1.19 | S13: 25 | T13: Umm Al Quwain | U13: Successful | V13: Manual Credit Card | W13: Separate Invoice | X13: No | Z13: 1
A14: Stray Dogs Center | B14: 46052 | C14: Past | D14: 67142 | E14: 40246 | F14: Stray Dogs Center | G14: - | H14: No | I14: 46050 | J14: 46050.556 | K14: - | L14: Samples x 1 | M14: 30-01-2026 | N14: Not Subscribed | O14: 0 | P14: 0 | Q14: 25 | R14: 1.19 | S14: 25 | T14: Umm Al Quwain | U14: Successful | V14: Manual Credit Card | W14: Separate Invoice | X14: No | Z14: 1
A15: Stray Dogs Center | B15: 46059 | C15: Past | D15: 67398 | E15: 40246 | F15: Stray Dogs Center | G15: - | H15: No | I15: 46057 | J15: 46057.373 | K15: - | L15: Samples x 1 | M15: 06-02-2026 | N15: Not Subscribed | O15: 0 | P15: 0 | Q15: 25 | R15: 1.19 | S15: 25 | T15: Umm Al Quwain | U15: Successful | V15: Manual Credit Card | W15: Separate Invoice | X15: No | Z15: 1
A16: Stray Dogs Center | B16: 46066 | C16: Past | D16: 67399 | E16: 40246 | F16: Stray Dogs Center | G16: - | H16: No | I16: 46057 | J16: 46057.374 | K16: - | L16: Samples x 1 | M16: 13-02-2026 | N16: Not Subscribed | O16: 0 | P16: 0 | Q16: 25 | R16: 1.19 | S16: 25 | T16: Umm Al Quwain | U16: Successful | V16: Manual Credit Card | W16: Separate Invoice | X16: No | Z16: 1
A17: Stray Dogs Center | B17: 46073 | C17: Past | D17: 67919 | E17: 40246 | F17: Stray Dogs Center | G17: - | H17: No | I17: 46071 | J17: 46071 | K17: - | L17: Samples x 1 | M17: 20-02-2026 | N17: Not Subscribed | O17: 0 | P17: 0 | Q17: 25 | R17: 1.19 | S17: 25 | T17: Umm Al Quwain | U17: Successful | V17: Manual Credit Card | W17: Separate Invoice | X17: No
A18: Stray Dogs Center | B18: 46080 | C18: Past | D18: 67920 | E18: 40246 | F18: Stray Dogs Center | G18: - | H18: No | I18: 46071 | J18: 46071.444 | K18: - | L18: Samples x 1 | M18: 27-02-2026 | N18: Not Subscribed | O18: 0 | P18: 0 | Q18: 25 | R18: 1.19 | S18: 25 | T18: Umm Al Quwain | U18: Successful | V18: Manual Credit Card | W18: Separate Invoice | X18: No | Z18: 1
A19: Stray Dogs Center | B19: 46094 | C19: Past | D19: 67922 | E19: 40246 | F19: Stray Dogs Center | G19: - | H19: No | I19: 46071 | J19: 46071.443 | K19: - | L19: Samples x 1 | M19: 13-03-2026 | N19: Not Subscribed | O19: 0 | P19: 0 | Q19: 25 | R19: 1.19 | S19: 25 | T19: Umm Al Quwain | U19: Successful | V19: Manual Credit Card | W19: Separate Invoice | X19: No | Z19: 1
A20: Stray Dogs Center | B20: 46101 | C20: Past | D20: 67921 | E20: 40246 | F20: Stray Dogs Center | G20: - | H20: No | I20: 46071 | J20: 46071 | K20: - | L20: Samples x 1 | M20: 20-03-2026 | N20: Not Subscribed | O20: 0 | P20: 0 | Q20: 25 | R20: 1.19 | S20: 25 | T20: Umm Al Quwain | U20: Successful | V20: Manual Credit Card | W20: Separate Invoice | X20: No
A21: Stray Dogs Center | B21: 46115 | C21: Past | D21: 69383 | E21: 40246 | F21: Stray Dogs Center | G21: - | H21: No | I21: 46114 | J21: 46114.352 | K21: - | L21: Samples x 1 | M21: 03-04-2026 | N21: Not Subscribed | O21: 0 | P21: 0 | Q21: 25 | R21: 1.19 | S21: 25 | T21: Umm Al Quwain | U21: Successful | V21: Manual Credit Card | W21: Separate Invoice | X21: No | Z21: 1
A22: Stray Dogs Center | B22: 46136 | C22: Past | D22: 69718 | E22: 40246 | F22: Stray Dogs Center | G22: - | H22: No | I22: 46125 | K22: - | L22: Samples x 1 | M22: 24-04-2026 | N22: Not Subscribed | O22: 0 | P22: 0 | Q22: 25 | R22: 1.19 | S22: 25 | T22: Umm Al Quwain | U22: Abandoned | V22: Manual Credit Card | W22: Separate Invoice | X22: No
A23: Stray Dogs Center | B23: 46150 | C23: Past | D23: 70691 | E23: 40246 | F23: Stray Dogs Center | G23: - | H23: No | I23: 46149 | J23: 46149 | K23: - | L23: Samples x 1 | M23: 08-05-2026 | N23: Not Subscribed | O23: 0 | P23: 0 | Q23: 25 | R23: 1.19 | S23: 25 | T23: Umm Al Quwain | U23: Successful | V23: Manual Credit Card | W23: Separate Invoice | X23: No | Y23: 60kg Gift a Meal scheduled for delivery
A24: Stray Dogs Center | B24: 46164 | C24: Past | D24: 71172 | E24: 40246 | F24: Stray Dogs Center | G24: - | H24: No | I24: 46162 | K24: - | L24: Samples x 1 | M24: 22-05-2026 | N24: Not Subscribed | O24: 0 | P24: 0 | Q24: 25 | R24: 1.19 | S24: 25 | T24: Umm Al Quwain | U24: Processing | V24: Manual Credit Card | W24: Separate Invoice | X24: No | Z24: 1
A25: Stray Dogs Center | B25: 46178 | C25: Past | D25: 71614 | E25: 40246 | F25: Stray Dogs Center | G25: - | H25: No | I25: 46175 | J25: 46175.445 | K25: - | L25: Samples x 1 | M25: 05-06-2026 | N25: Not Subscribed | O25: 0 | P25: 0 | Q25: 25 | R25: 1.19 | S25: 25 | T25: Umm Al Quwain | U25: Successful | V25: Manual Credit Card | W25: Separate Invoice | X25: No | Z25: 1
A26: Stray Dogs Center | B26: 46192 | C26: Past | D26: 72067 | E26: 40246 | F26: Stray Dogs Center | G26: - | H26: No | I26: 46189 | J26: 46189.28 | K26: - | L26: Samples x 1 | M26: 19-06-2026 | N26: Not Subscribed | O26: 0 | P26: 0 | Q26: 25 | R26: 1.19 | S26: 25 | T26: Umm Al Quwain | U26: Successful | V26: Manual Credit Card | W26: Separate Invoice | X26: No | Z26: 1
A27: Stray Dogs Center | B27: 46206 | C27: Past | D27: 72068 | E27: 40246 | F27: Stray Dogs Center | G27: - | H27: No | I27: 46189 | J27: 46189.28 | K27: - | L27: Samples x 1 | M27: 03-07-2026 | N27: Not Subscribed | O27: 0 | P27: 0 | Q27: 25 | R27: 1.19 | S27: 25 | T27: Umm Al Quwain | U27: Successful | V27: Manual Credit Card | W27: Separate Invoice | X27: No | Z27: 1
A28: Stray Dogs Center | B28: 46220 | C28: Past | D28: 73037 | E28: 40246 | F28: Stray Dogs Center | G28: - | H28: No | I28: 46210 | J28: 46219.308 | K28: - | L28: Samples x 1 | M28: 17-07-2026 | N28: Not Subscribed | O28: 0 | P28: 0 | Q28: 25 | R28: 1.19 | S28: 25 | T28: Umm Al Quwain | U28: Successful | V28: Manual Credit Card | W28: Separate Invoice | X28: No | Z28: 1
A29: Stray Dogs Center | B29: 46234 | C29: Past | D29: 74061 | E29: 40246 | F29: Stray Dogs Center | G29: - | H29: No | I29: 46233 | J29: 46233.465 | K29: - | L29: Samples x 1 | M29: 31-07-2026 | N29: Not Subscribed | O29: 0 | P29: 0 | Q29: 25 | R29: 1.19 | S29: 25 | T29: Umm Al Quwain | U29: Successful | V29: Manual Credit Card | W29: Separate Invoice | X29: No | Z29: 1
A30: Stray Dogs Center | B30: 46251 | C30: Past | D30: 74790 | E30: 40246 | F30: Stray Dogs Center | G30: - | H30: No | I30: 46249 | K30: - | L30: Samples x 1 | M30: 17-08-2026 | N30: Not Subscribed | O30: 0 | P30: 25 | Q30: 0 | R30: 0 | S30: 25 | T30: Umm Al Quwain | U30: Successful | V30: Complimentary | W30: Separate Invoice | X30: No
A31: Stray Dogs Center | B31: 46262 | C31: Past | D31: 75004 | E31: 40246 | F31: Stray Dogs Center | G31: - | H31: No | I31: 46253 | K31: - | L31: Samples x 1 | M31: 28-08-2026 | N31: Not Subscribed | O31: 0 | P31: 0 | Q31: 25 | R31: 1.19 | S31: 25 | T31: Umm Al Quwain | U31: Abandoned | V31: Manual Credit Card | W31: Separate Invoice | X31: No
A32: Stray Dogs Center | B32: 46262 | C32: Past | D32: 75427 | E32: 40246 | F32: Stray Dogs Center | G32: - | H32: No | I32: 46261 | K32: - | L32: Samples x 1 | M32: 28-08-2026 | N32: Not Subscribed | O32: 0 | P32: 0 | Q32: 0 | R32: 0 | S32: 0 | T32: Umm Al Quwain | U32: Successful | V32: Complimentary | W32: Separate Invoice | X32: No
A33: Stray Dogs Center | B33: 46277 | C33: Past | D33: 75005 | E33: 40246 | F33: Stray Dogs Center | G33: - | H33: No | I33: 46253 | K33: - | L33: Samples x 1 | M33: 12-09-2026 | N33: Not Subscribed | O33: 0 | P33: 0 | Q33: 25 | R33: 1.19 | S33: 25 | T33: Umm Al Quwain | U33: Abandoned | V33: Manual Credit Card | W33: Separate Invoice | X33: No
A34: Stray Dogs Center | B34: 46290 | C34: Upcoming | D34: 75006 | E34: 40246 | F34: Stray Dogs Center | G34: - | H34: No | I34: 46253 | K34: - | L34: Samples x 1 | M34: 25-09-2026 | N34: Not Subscribed | O34: 0 | P34: 0 | Q34: 25 | R34: 1.19 | S34: 25 | T34: Umm Al Quwain | U34: Abandoned | V34: Manual Credit Card | W34: Separate Invoice | X34: No
A35: Stray Dogs Center | B35: 46304 | C35: Upcoming | D35: 75007 | E35: 40246 | F35: Stray Dogs Center | G35: - | H35: No | I35: 46253 | K35: - | L35: Samples x 1 | M35: 09-10-2026 | N35: Not Subscribed | O35: 0 | P35: 0 | Q35: 25 | R35: 1.19 | S35: 25 | T35: Umm Al Quwain | U35: Abandoned | V35: Manual Credit Card | W35: Separate Invoice | X35: No
A36: Stray Dogs Center | B36: 46318 | C36: Upcoming | D36: 75008 | E36: 40246 | F36: Stray Dogs Center | G36: - | H36: No | I36: 46253 | K36: - | L36: Samples x 1 | M36: 23-10-2026 | N36: Not Subscribed | O36: 0 | P36: 0 | Q36: 25 | R36: 1.19 | S36: 25 | T36: Umm Al Quwain | U36: Abandoned | V36: Manual Credit Card | W36: Separate Invoice | X36: No
A37: Haven of Hope | B37: 46140 | C37: Past | D37: 70265 | E37: 41785 | F37: Haven Of Hope Rescue | G37: - | H37: No | I37: 46139 | J37: 46139 | K37: - | L37: Samples x 1 | M37: 28-04-2026 | N37: Not Subscribed | O37: 0 | P37: 0 | Q37: 0 | R37: 0 | S37: 0 | T37: Dubai | U37: Successful | V37: Complimentary | W37: Separate Invoice | X37: No
A38: Haven of Hope | B38: 46258 | C38: Past | D38: 75013 | E38: 41785 | F38: Haven Of Hope Rescue | G38: - | H38: No | I38: 46246 | K38: - | L38: Samples x 1 | M38: 24-08-2026 | N38: Not Subscribed | O38: 0 | P38: 0 | Q38: 0 | R38: 0 | S38: 0 | T38: Dubai | U38: Successful | V38: Complimentary | W38: Separate Invoice | X38: No
A39: Haven of Hope | B39: 46272 | C39: Past | D39: 75014 | E39: 41785 | F39: Haven Of Hope Rescue | G39: - | H39: No | I39: 46253 | K39: - | L39: Samples x 1 | M39: 07-09-2026 | N39: Not Subscribed | O39: 0 | P39: 0 | Q39: 0 | R39: 0 | S39: 0 | T39: Dubai | U39: Successful | V39: Complimentary | W39: Separate Invoice | X39: No
A40: Haven of Hope | B40: 46286 | C40: Upcoming | D40: 75015 | E40: 41785 | F40: Haven Of Hope Rescue | G40: - | H40: No | I40: 46253 | K40: - | L40: Samples x 1 | M40: 21-09-2026 | N40: Not Subscribed | O40: 0 | P40: 0 | Q40: 0 | R40: 0 | S40: 0 | T40: Dubai | U40: Successful | V40: Complimentary | W40: Separate Invoice | X40: No
A41: Haven of Hope | B41: 46300 | C41: Upcoming | D41: 76265 | E41: 41785 | F41: Haven Of Hope Rescue | G41: - | H41: No | I41: 46280 | K41: - | L41: Samples x 1 | M41: 05-10-2026 | N41: Not Subscribed | O41: 0 | P41: 0 | Q41: 0 | R41: 0 | S41: 0 | T41: Dubai | U41: Successful | V41: Complimentary | W41: Separate Invoice | X41: No | Y41: Gift a Meal for Haven of Hope, already marked as successful in donation deliveries
...

Sheet Summary by Shelter
A1: Summary by Shelter
A2: All figures are formulas over the "All Shelter Checkouts" tab. Amounts in AED.
A4: Shelter | B4: Region | C4: Total checkouts | D4: Upcoming | E4: Past | F4: Successful | G4: Abandoned | H4: Processing | I4: Earliest delivery | J4: Latest delivery | K4: Total Amount (AED)
A5: Stray Dogs Center | B5: Umm Al Quwain | C5: =COUNTIF('All Shelter Checkouts'!$A$5:$A$68,$A5) | D5: =COUNTIFS('All Shelter Checkouts'!$A$5:$A$68,$A5,'All Shelter Checkouts'!$C$5:$C$68,"Upcoming") | E5: =COUNTIFS('All Shelter Checkouts'!$A$5:$A$68,$A5,'All Shelter Checkouts'!$C$5:$C$68,"Past") | F5: =COUNTIFS('All Shelter Checkouts'!$A$5:$A$68,$A5,'All Shelter Checkouts'!$U$5:$U$68,"Successful") | G5: =COUNTIFS('All Shelter Checkouts'!$A$5:$A$68,$A5,'All Shelter Checkouts'!$U$5:$U$68,"Abandoned") | H5: =COUNTIFS('All Shelter Checkouts'!$A$5:$A$68,$A5,'All Shelter Checkouts'!$U$5:$U$68,"Processing") | I5: =_xlfn.MINIFS('All Shelter Checkouts'!$B$5:$B$68,'All Shelter Checkouts'!$A$5:$A$68,$A5) | J5: =_xlfn.MAXIFS('All Shelter Checkouts'!$B$5:$B$68,'All Shelter Checkouts'!$A$5:$A$68,$A5) | K5: =SUMIF('All Shelter Checkouts'!$A$5:$A$68,$A5,'All Shelter Checkouts'!$Q$5:$Q$68)
A6: Haven of Hope | B6: Dubai | C6: =COUNTIF('All Shelter Checkouts'!$A$5:$A$68,$A6) | D6: =COUNTIFS('All Shelter Checkouts'!$A$5:$A$68,$A6,'All Shelter Checkouts'!$C$5:$C$68,"Upcoming") | E6: =COUNTIFS('All Shelter Checkouts'!$A$5:$A$68,$A6,'All Shelter Checkouts'!$C$5:$C$68,"Past") | F6: =COUNTIFS('All Shelter Checkouts'!$A$5:$A$68,$A6,'All Shelter Checkouts'!$U$5:$U$68,"Successful") | G6: =COUNTIFS('All Shelter Checkouts'!$A$5:$A$68,$A6,'All Shelter Checkouts'!$U$5:$U$68,"Abandoned") | H6: =COUNTIFS('All Shelter Checkouts'!$A$5:$A$68,$A6,'All Shelter Checkouts'!$U$5:$U$68,"Processing") | I6: =_xlfn.MINIFS('All Shelter Checkouts'!$B$5:$B$68,'All Shelter Checkouts'!$A$5:$A$68,$A6) | J6: =_xlfn.MAXIFS('All Shelter Checkouts'!$B$5:$B$68,'All Shelter Checkouts'!$A$5:$A$68,$A6) | K6: =SUMIF('All Shelter Checkouts'!$A$5:$A$68,$A6,'All Shelter Checkouts'!$Q$5:$Q$68)
A7: Second Chance Animal Sanctuary | B7: RAK | C7: =COUNTIF('All Shelter Checkouts'!$A$5:$A$68,$A7) | D7: =COUNTIFS('All Shelter Checkouts'!$A$5:$A$68,$A7,'All Shelter Checkouts'!$C$5:$C$68,"Upcoming") | E7: =COUNTIFS('All Shelter Checkouts'!$A$5:$A$68,$A7,'All Shelter Checkouts'!$C$5:$C$68,"Past") | F7: =COUNTIFS('All Shelter Checkouts'!$A$5:$A$68,$A7,'All Shelter Checkouts'!$U$5:$U$68,"Successful") | G7: =COUNTIFS('All Shelter Checkouts'!$A$5:$A$68,$A7,'All Shelter Checkouts'!$U$5:$U$68,"Abandoned") | H7: =COUNTIFS('All Shelter Checkouts'!$A$5:$A$68,$A7,'All Shelter Checkouts'!$U$5:$U$68,"Processing") | I7: =_xlfn.MINIFS('All Shelter Checkouts'!$B$5:$B$68,'All Shelter Checkouts'!$A$5:$A$68,$A7) | J7: =_xlfn.MAXIFS('All Shelter Checkouts'!$B$5:$B$68,'All Shelter Checkouts'!$A$5:$A$68,$A7) | K7: =SUMIF('All Shelter Checkouts'!$A$5:$A$68,$A7,'All Shelter Checkouts'!$Q$5:$Q$68)
A8: RAK Animal Welfare Centre | B8: RAK | C8: =COUNTIF('All Shelter Checkouts'!$A$5:$A$68,$A8) | D8: =COUNTIFS('All Shelter Checkouts'!$A$5:$A$68,$A8,'All Shelter Checkouts'!$C$5:$C$68,"Upcoming") | E8: =COUNTIFS('All Shelter Checkouts'!$A$5:$A$68,$A8,'All Shelter Checkouts'!$C$5:$C$68,"Past") | F8: =COUNTIFS('All Shelter Checkouts'!$A$5:$A$68,$A8,'All Shelter Checkouts'!$U$5:$U$68,"Successful") | G8: =COUNTIFS('All Shelter Checkouts'!$A$5:$A$68,$A8,'All Shelter Checkouts'!$U$5:$U$68,"Abandoned") | H8: =COUNTIFS('All Shelter Checkouts'!$A$5:$A$68,$A8,'All Shelter Checkouts'!$U$5:$U$68,"Processing") | I8: =_xlfn.MINIFS('All Shelter Checkouts'!$B$5:$B$68,'All Shelter Checkouts'!$A$5:$A$68,$A8) | J8: =_xlfn.MAXIFS('All Shelter Checkouts'!$B$5:$B$68,'All Shelter Checkouts'!$A$5:$A$68,$A8) | K8: =SUMIF('All Shelter Checkouts'!$A$5:$A$68,$A8,'All Shelter Checkouts'!$Q$5:$Q$68)
A9: A's Ark Rescue | B9: Dubai | C9: =COUNTIF('All Shelter Checkouts'!$A$5:$A$68,$A9) | D9: =COUNTIFS('All Shelter Checkouts'!$A$5:$A$68,$A9,'All Shelter Checkouts'!$C$5:$C$68,"Upcoming") | E9: =COUNTIFS('All Shelter Checkouts'!$A$5:$A$68,$A9,'All Shelter Checkouts'!$C$5:$C$68,"Past") | F9: =COUNTIFS('All Shelter Checkouts'!$A$5:$A$68,$A9,'All Shelter Checkouts'!$U$5:$U$68,"Successful") | G9: =COUNTIFS('All Shelter Checkouts'!$A$5:$A$68,$A9,'All Shelter Checkouts'!$U$5:$U$68,"Abandoned") | H9: =COUNTIFS('All Shelter Checkouts'!$A$5:$A$68,$A9,'All Shelter Checkouts'!$U$5:$U$68,"Processing") | I9: =_xlfn.MINIFS('All Shelter Checkouts'!$B$5:$B$68,'All Shelter Checkouts'!$A$5:$A$68,$A9) | J9: =_xlfn.MAXIFS('All Shelter Checkouts'!$B$5:$B$68,'All Shelter Checkouts'!$A$5:$A$68,$A9) | K9: =SUMIF('All Shelter Checkouts'!$A$5:$A$68,$A9,'All Shelter Checkouts'!$Q$5:$Q$68)
A10: Total | C10: =SUM(C5:C9) | D10: =SUM(D5:D9) | E10: =SUM(E5:E9) | F10: =SUM(F5:F9) | G10: =SUM(G5:G9) | H10: =SUM(H5:H9) | I10: =MIN(I5:I9) | J10: =MAX(J5:J9) | K10: =SUM(K5:K9)

Sheet Notes & Method
A1: Notes & Method
A3: Source file | B3: checkouts_template_2025-01-01_to_2027-12-31.xlsx, sheet "Checkouts (Template)" (19,350 checkout rows).
A5: Prepared | B5: 19 September 2026.
A7: Shelters requested | B7: Stray Dogs Center; Haven of Hope; Second Chance Animal Sanctuary; RAK Animal Welfare Centre; A's Ark Rescue.
A9: How they were matched | B9: Matched on "Customer Name" in the source. Names as stored: "Stray Dogs Center" (Customer # 40246), "Haven Of Hope Rescue" (41785), "Second Chance Animal Sanctuary" (29813), "RAKAWC" (27502), "A's Ark Rescue" (43473). RAKAWC = RAK Animal Welfare Centre, confirmed by Mariette. Each shelter maps to exactly one customer number; no other name variants or duplicate accounts were found.
A11: "Scheduled" - important | B11: The source has a Status column whose forward-looking values are "Scheduled" and "Arranged". NO checkout for any of these five shelters carries either status - all 64 of their checkouts are Checkout Type "Separate Invoice", which in this export only ever takes Successful / Abandoned / Processing. "Scheduled" is therefore interpreted here as scheduled-for-delivery: a checkout whose Delivery Date falls on or after 19 Sep 2026.
A13: Upcoming Checkouts tab | B13: The 5 checkouts meeting that test, ordered by delivery date. Note 3 of them (Stray Dogs Center) have Status "Abandoned", i.e. raised but not settled - they are included so nothing is hidden, but they should be confirmed before being treated as firm deliveries.
A15: All Shelter Checkouts tab | B15: All 64 checkouts for the five shelters, so the upcoming ones can be read in context. Upcoming rows are shaded yellow.
A17: Delivery Date column | B17: Added by this extract: the source "Delivery Dates" text parsed to a real date. Every shelter row holds a single date (no multi-date subscription schedules), so the parse is one-to-one. Both columns are shown.
A19: Timing column | B19: Added by this extract: "Upcoming" if Delivery Date >= 19 Sep 2026, otherwise "Past".
A21: Columns dropped | B21: Source columns empty for all 64 rows were omitted: Customer Pets; Delivery Plan; Failure Reason. The running "No." index was also dropped as it refers to the full 19,350-row export. Every other source column is kept unchanged.
A23: Constant columns kept | B23: These are identical on all 64 rows and kept for completeness: Subscription Plan = "-"; Wunderbar = "No"; End of Subscription = "-"; Subscription Status = "Not Subscribed"; Checkout Type = "Separate Invoice"; Donation = "No".
A25: Amounts | B25: AED, copied from the source unchanged. Most shelter checkouts are Complimentary (Gift a Meal donations) at AED 0; the AED 25 lines are delivery charges on Manual Credit Card checkouts.
A27: Figures on Summary tab | B27: All live formulas over the All Shelter Checkouts tab - they update if rows are edited or added.
